Compilation warnings/errors on ../sol_file/send_loop.sol:
../sol_file/send_loop.sol:14:13: Error: Expected identifier, got 'LParen'
	constructor() {
	           ^

Traceback (most recent call last):
  File "/home/charlesdjl/miniconda3/envs/slither/lib/python3.10/site-packages/crytic_compile-0.3.1-py3.10.egg/crytic_compile/platform/solc.py", line 561, in _run_solc
    ret: Dict = json.loads(stdout)
  File "/home/charlesdjl/miniconda3/envs/slither/lib/python3.10/json/__init__.py", line 346, in loads
    return _default_decoder.decode(s)
  File "/home/charlesdjl/miniconda3/envs/slither/lib/python3.10/json/decoder.py", line 337, in decode
    obj, end = self.raw_decode(s, idx=_w(s, 0).end())
  File "/home/charlesdjl/miniconda3/envs/slither/lib/python3.10/json/decoder.py", line 355, in raw_decode
    raise JSONDecodeError("Expecting value", s, err.value) from None
json.decoder.JSONDecodeError: Expecting value: line 1 column 1 (char 0)

During handling of the above exception, another exception occurred:

Traceback (most recent call last):
  File "/home/charlesdjl/miniconda3/envs/slither/lib/python3.10/site-packages/slither_analyzer-0.9.3-py3.10.egg/slither/__main__.py", line 837, in main_impl
    ) = process_all(filename, args, detector_classes, printer_classes)
  File "/home/charlesdjl/miniconda3/envs/slither/lib/python3.10/site-packages/slither_analyzer-0.9.3-py3.10.egg/slither/__main__.py", line 90, in process_all
    compilations = compile_all(target, **vars(args))
  File "/home/charlesdjl/miniconda3/envs/slither/lib/python3.10/site-packages/crytic_compile-0.3.1-py3.10.egg/crytic_compile/crytic_compile.py", line 643, in compile_all
    compilations.append(CryticCompile(target, **kwargs))
  File "/home/charlesdjl/miniconda3/envs/slither/lib/python3.10/site-packages/crytic_compile-0.3.1-py3.10.egg/crytic_compile/crytic_compile.py", line 131, in __init__
    self._compile(**kwargs)
  File "/home/charlesdjl/miniconda3/envs/slither/lib/python3.10/site-packages/crytic_compile-0.3.1-py3.10.egg/crytic_compile/crytic_compile.py", line 553, in _compile
    self._platform.compile(self, **kwargs)
  File "/home/charlesdjl/miniconda3/envs/slither/lib/python3.10/site-packages/crytic_compile-0.3.1-py3.10.egg/crytic_compile/platform/solc.py", line 156, in compile
    targets_json = _get_targets_json(compilation_unit, self._target, **kwargs)
  File "/home/charlesdjl/miniconda3/envs/slither/lib/python3.10/site-packages/crytic_compile-0.3.1-py3.10.egg/crytic_compile/platform/solc.py", line 285, in _get_targets_json
    return _run_solc(
  File "/home/charlesdjl/miniconda3/envs/slither/lib/python3.10/site-packages/crytic_compile-0.3.1-py3.10.egg/crytic_compile/platform/solc.py", line 565, in _run_solc
    raise InvalidCompilation(f"Invalid solc compilation {stderr}")
crytic_compile.platform.exceptions.InvalidCompilation: Invalid solc compilation ../sol_file/send_loop.sol:14:13: Error: Expected identifier, got 'LParen'
	constructor() {
	           ^

ERROR:root:Error in ../sol_file/send_loop.sol
ERROR:root:Traceback (most recent call last):
  File "/home/charlesdjl/miniconda3/envs/slither/lib/python3.10/site-packages/crytic_compile-0.3.1-py3.10.egg/crytic_compile/platform/solc.py", line 561, in _run_solc
    ret: Dict = json.loads(stdout)
  File "/home/charlesdjl/miniconda3/envs/slither/lib/python3.10/json/__init__.py", line 346, in loads
    return _default_decoder.decode(s)
  File "/home/charlesdjl/miniconda3/envs/slither/lib/python3.10/json/decoder.py", line 337, in decode
    obj, end = self.raw_decode(s, idx=_w(s, 0).end())
  File "/home/charlesdjl/miniconda3/envs/slither/lib/python3.10/json/decoder.py", line 355, in raw_decode
    raise JSONDecodeError("Expecting value", s, err.value) from None
json.decoder.JSONDecodeError: Expecting value: line 1 column 1 (char 0)

During handling of the above exception, another exception occurred:

Traceback (most recent call last):
  File "/home/charlesdjl/miniconda3/envs/slither/lib/python3.10/site-packages/slither_analyzer-0.9.3-py3.10.egg/slither/__main__.py", line 837, in main_impl
    ) = process_all(filename, args, detector_classes, printer_classes)
  File "/home/charlesdjl/miniconda3/envs/slither/lib/python3.10/site-packages/slither_analyzer-0.9.3-py3.10.egg/slither/__main__.py", line 90, in process_all
    compilations = compile_all(target, **vars(args))
  File "/home/charlesdjl/miniconda3/envs/slither/lib/python3.10/site-packages/crytic_compile-0.3.1-py3.10.egg/crytic_compile/crytic_compile.py", line 643, in compile_all
    compilations.append(CryticCompile(target, **kwargs))
  File "/home/charlesdjl/miniconda3/envs/slither/lib/python3.10/site-packages/crytic_compile-0.3.1-py3.10.egg/crytic_compile/crytic_compile.py", line 131, in __init__
    self._compile(**kwargs)
  File "/home/charlesdjl/miniconda3/envs/slither/lib/python3.10/site-packages/crytic_compile-0.3.1-py3.10.egg/crytic_compile/crytic_compile.py", line 553, in _compile
    self._platform.compile(self, **kwargs)
  File "/home/charlesdjl/miniconda3/envs/slither/lib/python3.10/site-packages/crytic_compile-0.3.1-py3.10.egg/crytic_compile/platform/solc.py", line 156, in compile
    targets_json = _get_targets_json(compilation_unit, self._target, **kwargs)
  File "/home/charlesdjl/miniconda3/envs/slither/lib/python3.10/site-packages/crytic_compile-0.3.1-py3.10.egg/crytic_compile/platform/solc.py", line 285, in _get_targets_json
    return _run_solc(
  File "/home/charlesdjl/miniconda3/envs/slither/lib/python3.10/site-packages/crytic_compile-0.3.1-py3.10.egg/crytic_compile/platform/solc.py", line 565, in _run_solc
    raise InvalidCompilation(f"Invalid solc compilation {stderr}")
crytic_compile.platform.exceptions.InvalidCompilation: Invalid solc compilation ../sol_file/send_loop.sol:14:13: Error: Expected identifier, got 'LParen'
	constructor() {
	           ^


分析时间：9.149921133 s
==== Multiple Calls in a Single Transaction ====
SWC ID: 113
Severity: Low
Contract: Refunder
Function name: refundAll()
PC address: 431
Estimated Gas Usage: 12970 - 83517
Multiple calls are executed in the same transaction.
This call is executed following another call within the same transaction. It is possible that the call never gets executed if a prior call fails permanently. This might be caused intentionally by a malicious callee. If possible, refactor the code such that each transaction only executes one external call or make sure that all callees can be trusted (i.e. they’re part of your own codebase).
--------------------
In file: ../sol_file/send_loop.sol:22

refundAddresses[x].send(refunds[refundAddresses[x]])

--------------------
Initial State:

Account: [CREATOR], balance: 0x0, nonce:0, storage:{}
Account: [ATTACKER], balance: 0x0, nonce:0, storage:{}

Transaction Sequence:

Caller: [CREATOR], calldata: , decoded_data: , value: 0x0
Caller: [ATTACKER], function: refundAll(), txdata: 0x38e771ab, value: 0x0
